Workbook

Sheet Summary
A1: Сводка расчёта — ключевые результаты
A2: Ввод (INPUT) | B2: Расчёт / Итог (bold) | C2: Проверка ✓/✗ — окрашивается по результату
A4: Проверка осуществимости конфигурации
A5: Модель помещается на сервер | B5: =Sizing!D13
A6: Th_pf / roofline | B6: =Sizing!D34 | C6: ×
A8: Диагностика / предупреждения
A9: K_batch over-stretch (Th_pf > 1.5× roofline) | B9: =IF(Sizing!D34>1.5,"⚠ Th_pf > 1.5× roofline — возможно завышение Th_pf через K_batch. Снизьте C или переключите engine_mode=continuous","✓ OK")
A10: Th_pf_emp / Th_dec_emp vs η калибровка | B10: =IF(OR(AND(Inputs!D65>0,Inputs!D61=0.2),AND(Inputs!D66>0,Inputs!D63=0.3)),"⚠ Эмпирический Th_* задан, но η_pf/η_mem на дефолтных 0.20/0.30 — калибровочные коэффициенты не переcчитаны (§Е)","✓ OK")
A11: Agentic overlay применён в Inputs | B11: =IF(Agentic!D23<=1,"✓ n/a: K_calls=1 (не агентный сценарий)","✓ OK: агентные надбавки и K_calls учтены автоматически (Inputs, блок 2.3)")
A12: Сходимость итераций Servers | B12: =IF(ISNUMBER(SEARCH("OK",Sizing!D54)),"✓ OK: итерации сошлись",Sizing!D54)
A14: Входная нагрузка
A15: Всего одновременных сессий (S_sim) | B15: =Inputs!D12 | C15: sess.
A16: Запросов/с на сессию (R) | B16: =Inputs!D75 | C16: req/s
A17: Целевое TTFT_SLA | B17: =Inputs!D77 | C17: s
A18: Целевое e2eLatency_SLA | B18: =Inputs!D78 | C18: s
A20: Оборудование
A21: GPU | B21: =Inputs!D25 | C21: -
A22: GPU на сервер | B22: =Inputs!D29 | C22: pcs
A23: Множитель TP (Z) | B23: =Inputs!D31 | C23: -
A25: Модель
A26: LLM модель | B26: =Inputs!D35 | C26: -
A27: Квантизация | B27: =Inputs!D53 | C27: -
A28: P_total / P_active | B28: =Inputs!D36&" / "&Inputs!D37 | C28: B
A29: Архитектура | B29: =Inputs!D43 | C29: -
A31: Память
A32: M_model (веса) | B32: =Sizing!D5 | C32: GiB
A33: M_KV на сессию | B33: =Sizing!D7 | C33: GiB
A34: Сессий на экземпляр (S_TP=Z) | B34: =Sizing!D15 | C34: sess.
A35: Сессий на сервер (S_server) | B35: =Sizing!D21 | C35: sess.
A37: Производительность
A38: Th_pf (per-session) | B38: =Sizing!D33 | C38: tok/s
A39: Th_dec (per-session) | B39: =Sizing!D38 | C39: tok/s
A40: C^model (req/s на экземпляр) | B40: =Sizing!D39 | C40: req/s
A41: Th_server^comp (req/s на сервер) | B41: =Sizing!D40 | C41: req/s
A43: Latency
A44: TTFT_analyt | B44: =Sizing!D59 | C44: s
A45: e2eLatency_analyt | B45: =Sizing!D61 | C45: s
A46: e2eLatency_load | B46: =Sizing!D62 | C46: s
A48: SLA статус
A49: TTFT | B49: =IF(Inputs!D77<=0,"n/a: цель TTFT не задана",IF(Inputs!D77>=Sizing!D59,"✓ OK: в пределах SLA","✗ FAIL: превышение SLA"))
...

Sheet Inputs
A1: Методика расчёта GPU — Калькулятор параметров
A2: Ввод (INPUT) | B2: Расчёт / Итог (bold) | C2: Проверка ✓/✗ — окрашивается по результату
A4: 2. Определение нагрузки в пользователях
D5: Сегмент 1 | E5: Сегмент 2 | F5: Сегмент 3 | G5: Сегмент 4
A6: Название сегмента | B6: Напр.: ритейл, внутренние, VIP | C6: INPUT | D6: Внутренние | E6: Внешние
A7: Число пользователей (N_users) | B7: Всего пользователей в сегменте | C7: INPUT | D7: 50000 | E7: 10000 | F7: 0 | G7: 0 | H7: users
A8: Коэф. проникновения (K_pen) | B8: Доля использующих GenAI, 0–1 | C8: INPUT | D8: 0.3 | E8: 0.2 | F8: 0 | G8: 0 | H8: ratio
A9: Коэф. одновременности (K_sim) | B9: Доля одновременно активных пользователей | C9: INPUT | D9: 0.1 | E9: 0.15 | F9: 0 | G9: 0 | H9: ratio
A10: Сессий на пользователя (J) | B10: Обычно 1 | C10: INPUT | D10: 1 | E10: 1 | F10: 1 | G10: 1 | H10: sess./user
A11: Одновременных сессий сегмента (S_sim,i) | B11: Формула: N_users · K_pen · K_sim · J | C11: calc | D11: =D7*D8*D9*D10 | E11: =E7*E8*E9*E10 | F11: =F7*F8*F9*F10 | G11: =G7*G8*G9*G10 | H11: sess.
A12: Всего одновременных сессий (S_sim) | B12: Сумма по всем сегментам | C12: calc | D12: =SUM(D11:G11) | H12: sess.
A14: 2.2. Токеновый профиль одной сессии
A15: Число токенов системного промпта (SP) | B15: По умолчанию 1000 (~1000 символов) | C15: INPUT | D15: 1000 | H15: tokens
A16: Число токенов входного запроса (Prp) | B16: По умолчанию 200 (~500 символов) | C16: INPUT | D16: 200 | H16: tokens
A17: Число токенов ответа модели (A) | B17: По умолчанию 400 (~900 символов) | C17: INPUT | D17: 400 | H17: tokens
A18: Бюджет токенов на reasoning (MRT) | B18: 0 если модель без reasoning; 20–50% от max для reasoning | C18: INPUT | D18: 0 | H18: tokens
A19: Число пар запрос-ответ в сессии (N_prp) | B19: По умолчанию 5 | C19: INPUT | D19: 5 | H19: pcs
A20: Полная длина сессии (TS) | B20: TS = SL_pf^raw + T_dec (§2.2). Для KV-кэша берётся SL = min(TS, TS_max). | C20: calc | D20: =D88+D22 | H20: tokens
A21: Длина входа на этапе prefill (SL_pf) | B21: SL_pf = min(SL_pf^raw, TS_max − T_dec) (§2.2). Для TTFT, Th_pf и Th_dec. | C21: calc | D21: =MIN(D88,D44-D22) | H21: tokens
A22: Число токенов decode (T_dec) | B22: T_dec = A_eff + MRT (§2.2, В.3): A_eff = A + A_tool. | C22: calc | D22: =D85+D86 | H22: tokens
A23: Reasoning прошлых ходов в истории (h_reason) | B23: 0 — движок отбрасывает reasoning прошлых ходов (по умолчанию); 1 — сохраняет (§2.2) | C23: INPUT | D23: 0 | E23: 0/1
A24: 4. Аппаратная конфигурация
A25: Модель GPU | B25: Выбрать из списка | C25: INPUT | D25: NVIDIA H100 GPU accelerator (SXM card) | H25: -
A26: Память одного GPU (GPU_memory) | B26: Авто из справочника | C26: lookup | D26: =IFERROR(INDEX(Reference!$B$3:$B$62,MATCH(D25,Reference!$A$3:$A$62,0)),0) | H26: GiB
A27: Пиковая производительность GPU (TFLOPS FP16) | B27: Авто из справочника | C27: lookup | D27: =IFERROR(INDEX(Reference!$C$3:$C$62,MATCH(D25,Reference!$A$3:$A$62,0)),0) | H27: TFLOPS
A28: Пропускная способность памяти GPU (BW_GPU) | B28: Авто из справочника | C28: lookup | D28: =IFERROR(INDEX(Reference!$D$3:$D$62,MATCH(D25,Reference!$A$3:$A$62,0)),0) | H28: GB/s
A29: Число GPU на сервере (GPU_count_server) | B29: Обычно 8 для DGX-класса | C29: INPUT | D29: 8 | H29: pcs
A30: Коэффициент доступной памяти (K_avail) | B30: Резерв под систему, обычно 0.9 | C30: INPUT | D30: 0.9 | H30: ratio
A31: Множитель TP (Z × TP_min) | B31: Итоговый TP на экземпляр = Z · TP_min. Пример: Z=4 при TP_min=2 → 8 GPU/экз. Условие: Z·TP_min ≤ GPU_count_server. | C31: INPUT | D31: 4 | H31: ×
A32: Ручной override числа серверов | B32: 0 = авто (max из mem/compute). Задайте >0, чтобы зафиксировать число серверов и посмотреть, выполняется ли SLA при такой конфигурации. | C32: INPUT | D32: 0 | H32: pcs
A34: 3. LLM модель
A35: Название модели | B35: Выбрать из списка | C35: INPUT | D35: Qwen3-30B-A3B | H35: -
A36: P_total (полное число параметров) | B36: Авто из справочника | C36: lookup | D36: =IFERROR(INDEX(Reference!$B$66:$B$265,MATCH(D35,Reference!$A$66:$A$265,0)),0) | H36: B
A37: P_active (активных параметров) | B37: Для dense = P_total; для MoE меньше | C37: lookup | D37: =IFERROR(INDEX(Reference!$C$66:$C$265,MATCH(D35,Reference!$A$66:$A$265,0)),0) | H37: B
A38: Число слоёв (L) | B38: Авто из справочника | C38: lookup | D38: =IFERROR(INDEX(Reference!$D$66:$D$265,MATCH(D35,Reference!$A$66:$A$265,0)),0) | H38: pcs
A39: Размер скрытого состояния (H) | B39: Авто из справочника | C39: lookup | D39: =IFERROR(INDEX(Reference!$E$66:$E$265,MATCH(D35,Reference!$A$66:$A$265,0)),0) | H39: pcs
A40: Число голов внимания (N_attention) | B40: Авто из справочника | C40: lookup | D40: =IFERROR(INDEX(Reference!$F$66:$F$265,MATCH(D35,Reference!$A$66:$A$265,0)),0) | H40: pcs
A41: Число KV-голов (N_kv) | B41: Авто из справочника. MHA: =N_attn; GQA: <N_attn; MQA: 1 | C41: lookup | D41: =IFERROR(INDEX(Reference!$G$66:$G$265,MATCH(D35,Reference!$A$66:$A$265,0)),0) | H41: pcs
A42: Размерность одной головы (head_dim) | B42: Авто из справочника | C42: lookup | D42: =IFERROR(INDEX(Reference!$H$66:$H$265,MATCH(D35,Reference!$A$66:$A$265,0)),0) | H42: pcs
A43: Архитектура | B43: Авто из справочника (справочно) | C43: lookup | D43: =IFERROR(INDEX(Reference!$I$66:$I$265,MATCH(D35,Reference!$A$66:$A$265,0)),0) | H43: -
...

Sheet Sizing
A1: Расчёт GPU-инфраструктуры — пошаговое вычисление
A2: Ввод (INPUT) | B2: Расчёт / Итог (bold) | C2: Проверка ✓/✗ — окрашивается по результату
A4: 3. Память GPU для модели и KV-кэша
A5: Память весов модели (M_model) | B5: (P_total · 10⁹ · B_quant / 1024³) · EMP_model + SM | C5: calc | D5: =(Inputs!D36*10^9*Inputs!D54)/1024^3*Inputs!D56+Inputs!D58 | E5: GiB | F5: 🟡 nvidia-smi
A6: SL для KV-кэша (min(TS, TS_max)) | B6: SL = SL_pf + T_dec = min(TS, TS_max) (§2.2) | C6: calc | D6: =MIN(Inputs!D20,Inputs!D44) | E6: tokens | F6: 🔵 methodology
A7: Память KV-кэша на 1 сессию (M_KV^S=1) | B7: MLA: L·(kv_lora_rank+qk_rope)·SL·B_state·EMP_kv/1024³; иначе: 2·L·N_kv·head_dim·SL·B_state·EMP_kv/1024³ | C7: calc | D7: =IF(Inputs!D47,Inputs!D38*(Inputs!D45+Inputs!D46)*D6*Inputs!D55*Inputs!D57/1024^3,2*Inputs!D38*Inputs!D41*Inputs!D42*D6*Inputs!D55*Inputs!D57/1024^3) | E7: GiB | F7: 🟡 nvidia-smi
A9: 4. Tensor Parallelism — оптимизация памяти
A10: Мин. число GPU на экземпляр (TP_min) | B10: CEILING(M_model / (GPU_memory · K_avail)) | C10: calc | D10: =CEILING(D5/(Inputs!D26*Inputs!D30),1) | E10: pcs | F10: 🔵 methodology
A11: GPU на экземпляр при TP=Z | B11: Z · GPU_count_min | C11: calc | D11: =Inputs!D31*D10 | E11: pcs | F11: 🔵 methodology
A12: Число экземпляров на сервер (N_TP=Z) | B12: FLOOR(GPU_count_server / GPU_per_inst) | C12: calc | D12: =FLOOR(Inputs!D29/D11,1) | E12: pcs | F12: 🟡 vLLM logs
A13: Модель помещается на сервер | B13: GPU_per_inst ≤ GPU_count_server | C13: calc | D13: =IF(D11<=Inputs!D29,"✓ OK","✗ FAIL: уменьшите Z или смените GPU — сейчас нужно "&D11&" GPU/экз., доступно "&Inputs!D29&" на сервере") | E13: status | F13: 🟢 deployment
A14: Свободная память под KV на экземпляр | B14: GPU_per_inst · GPU_memory · K_avail − M_model | C14: calc | D14: =D11*Inputs!D26*Inputs!D30-D5 | E14: GiB | F14: 🟡 nvidia-smi
A15: Макс. сессий на экземпляр (S_TP=Z) | B15: MLA: ⌊GPU_memForKV/(GPU_per_inst·M_KV)⌋ (латент реплицируется); иначе: ⌊GPU_memForKV·min(GPU_per_inst,N_kv)/(M_KV·GPU_per_inst)⌋ | C15: calc | D15: =IF(D7>0,IF(Inputs!D47,FLOOR(D14/(D11*D7),1),FLOOR(D14*MIN(D11,Inputs!D41)/(D7*D11),1)),0) | E15: sess. | F15: 🟡 vLLM logs
A16: Свободная память под KV при TP_min | B16: GPU_count_min · GPU_memory · K_avail − M_model | C16: calc | D16: =D10*Inputs!D26*Inputs!D30-D5 | E16: GiB | F16: 🟡 nvidia-smi
A17: Макс. сессий при TP=TP_min (S_TP=TP_min) | B17: База для K_batch (Z=1, TP=TP_min); стандарт: ⌊GPU_mem_kv_min·min(TP_min,N_kv)/(M_KV·TP_min)⌋; MLA: латент реплицируется на всех TP_min ранках | C17: calc | D17: =IF(D7>0,IF(Inputs!D47,FLOOR(D16/(D10*D7),1),FLOOR(D16*MIN(D10,Inputs!D41)/(D7*D10),1)),0) | E17: sess. | F17: 🟡 vLLM logs
A18: Коэф. прироста throughput от TP (K_batch) | B18: (S_TP=Z/S_TP=TP_min) · (S_TP=TP_min + C)/(S_TP=Z + C) | C18: calc | D18: =IF(AND(D17>0,D15>0),(D15/D17)*((D17+Inputs!D64)/(D15+Inputs!D64)),1) | E18: - | F18: 🔵 derived
A20: 5. Серверы по памяти
A21: Сессий на сервер (S_server) | B21: N_TP=Z · S_TP=Z | C21: calc | D21: =D12*D15 | E21: sess. | F21: 🟡 vLLM logs
A22: Число серверов по памяти (Servers_count^mem) | B22: ⌈S_sim / S_server⌉ | C22: calc | D22: =IF(D21>0,CEILING(Inputs!D12/D21,1),0) | E22: pcs | F22: 🟢 deployment
A24: 6. Пропускная способность и compute-сайзинг
A25: FLOP на токен (FPS) | B25: 2 · P_active · 10⁹ | C25: calc | D25: =2*Inputs!D37*10^9 | E25: FLOP/tok | F25: 🔵 derived
A26: Пиковая производительность экземпляра (F_count) | B26: GPU_per_inst · FLOPS_gpu · 10¹² (в FLOPs/sec) | C26: calc | D26: =D11*Inputs!D27*10^12 | E26: FLOP/s | F26: 🔵 spec lookup
A27: SL_pf эффективная (после префикс-кэша) | B27: SL_pf · (1 − η_cache); при η_cache=0 совпадает с SL_pf | C27: calc | D27: =Inputs!D21*(1-Inputs!D67) | E27: tokens | F27: 🔵 methodology
A28: BS_real итоговый (при S*) | B28: BS_real на сошедшемся состоянии §6.4 (лист Iterations) | C28: calc | D28: =Iterations!C33 | E28: sess. | F28: 🟡 vLLM logs
A29: Th_pf аналитическая (static batching) | B29: F_count · η_pf · K_batch / (FPS + 4·L·d_attn^pf·SL_pf). Только для static. | C29: calc | D29: =D26*Inputs!D61*D18/(D25+4*Inputs!D38*Inputs!D90*Inputs!D21) | E29: tok/s | F29: 🟢 EvalScope
A30: Th_pf^cb,compute (continuous, compute-bound) | B30: F_count · η_pf / (FPS + 4·L·d_attn^pf·SL_pf); attention по полному SL_pf (§6.1) | C30: calc | D30: =D26*Inputs!D61/(D25+4*Inputs!D38*Inputs!D90*Inputs!D21) | E30: tok/s | F30: 🟢 EvalScope
A31: Th_pf^cb,mem (continuous, memory-bound) | B31: C_pf·BW·10⁹·η_mem / (P_eff(BS+1)·10⁹·B_quant + BS·M_KV·1024³ + O_fixed·1024³) | C31: calc | D31: =Iterations!F33 | E31: tok/s | F31: 🟢 EvalScope
A32: Th_pf^cb (continuous batching итог) | B32: min(compute, mem) при BS_real итоговом | C32: calc | D32: =IF(AND(D30<=0,D31<=0),0,IF(D31<=0,D30,IF(D30<=0,D31,MIN(D30,D31)))) | E32: tok/s | F32: 🟢 EvalScope
A33: Th_pf выбранное (эмпир. / continuous / static) | B33: Th_pf_emp > 0 → эмпирический; иначе engine_mode=continuous → Th_pf^cb, engine_mode=static → Th_pf_analyt | C33: calc | D33: =Iterations!G33 | E33: tok/s | F33: 🟢 EvalScope
A34: Th_pf / roofline (санити-чек по FLOPS) | B34: <1.0: под потолком; 1.0-1.5: разумно; >1.5: K_batch завышает Th_pf | C34: calc | D34: =IF(D26>0,D33*(D25+4*Inputs!D38*Inputs!D90*Inputs!D21)/(D26*Inputs!D61),0) | E34: × | F34: 🔵 derived
A35: Th_dec^compute (per-session) | B35: F_count · η_dec / (FPS + 4·L·d_attn^dec·(SL_pf + (T_dec−1)/2)) / BS_real; без K_batch | C35: calc | D35: =Iterations!H33 | E35: tok/s/sess. | F35: 🔵 derived
A36: Th_dec^mem (per-session, memory-bound) | B36: BW_GPU·10⁹·η_mem / (P_eff(BS)·10⁹·B_quant + BS_real·M_KV·1024³ + O_fixed·1024³) | C36: calc | D36: =Iterations!I33 | E36: tok/s/sess. | F36: 🟢 EvalScope
A37: Th_dec аналитическая = min(compute, mem) | B37: Узкое место — минимум из двух пределов | C37: calc | D37: =IF(AND(D35<=0,D36<=0),0,IF(D36<=0,D35,IF(D35<=0,D36,MIN(D35,D36)))) | E37: tok/s/sess. | F37: 🟢 EvalScope
A38: Th_dec выбранное (эмпир. или аналит., с K_spec) | B38: Если Th_dec_emp > 0 — использовать его; иначе min(compute, mem). Далее: Th_dec · K_spec (спекулятивное декодирование, §3.1 H-5). | C38: calc | D38: =Iterations!J33 | E38: tok/s/sess. | F38: 🟢 EvalScope
A39: C^model(BS_real): запросов/с на экземпляр | B39: BS_real / (SL_pf^eff/Th_pf(BS) + T_dec/Th_dec(BS)) при BS_real итоговом | C39: calc | D39: =Iterations!K33 | E39: req/s | F39: 🟢 EvalScope
A40: Th_server_comp (req/s на сервер) | B40: N_TP=Z · C^model | C40: calc | D40: =Iterations!L33 | E40: req/s | F40: 🟢 EvalScope
A41: Серверов по compute (Servers_count^comp) | B41: ⌈S_sim · R_eff · K_SLA / Th_server_comp⌉ при S*; R_eff = R · K_calls | C41: calc | D41: =Iterations!M33 | E41: pcs | F41: 🟢 deployment
A42: §6.4 Итеративная резолюция BS_real ↔ Servers (полная таблица — лист Iterations)
A43: Servers^(0) | B43: Iterations: состояние k = 0 | C43: calc | D43: =Iterations!B6 | E43: pcs | F43: 🔵 derived
A44: Servers^(1) | B44: Iterations: состояние k = 1 | C44: calc | D44: =Iterations!B7 | E44: pcs | F44: 🔵 derived
...

Sheet Iterations
A1: §6.4 Итеративная резолюция BS_real ↔ Servers (шаги 1–4, k_max = 20)
A2: Каждая строка — одно состояние: Servers^(k) → BS_real → Th_pf(BS), Th_dec(BS) → C^model(BS) → Servers^comp → Servers^(k+1) = max(Servers_mem, Servers^comp). Сходимость — первая строка, где Servers^(k+1) = Servers^(k) (шаг 3 §6.4).
A4: Итерации
A5: k | B5: Servers^(k) | C5: BS_real | D5: P_eff(BS) | E5: P_eff(BS+1) | F5: Th_pf^cb,mem | G5: Th_pf | H5: Th_dec^comp/сесс | I5: Th_dec^mem/сесс | J5: Th_dec | K5: C^model | L5: Th_server | M5: Servers^comp | N5: Servers^(k+1) | O5: Сошлось
A6: 0 | B6: =Sizing!$D$22 | C6: =IF(AND(Sizing!$D$12>0,B6>0),MIN(IF(Sizing!$D$15>0,Sizing!$D$15,10^9),MAX(1,CEILING(Inputs!$D$12/(Sizing!$D$12*B6),1))),1) | D6: =IF(Inputs!$D$52,Inputs!$D$48+Inputs!$D$49*(1-POWER(1-Inputs!$D$50/Inputs!$D$51,C6)),Inputs!$D$37) | E6: =IF(Inputs!$D$52,Inputs!$D$48+Inputs!$D$49*(1-POWER(1-Inputs!$D$50/Inputs!$D$51,C6+1)),Inputs!$D$37) | F6: =IF(AND(Inputs!$D$28>0,Inputs!$D$70>0),Inputs!$D$70*Inputs!$D$28*10^9*Inputs!$D$63/(E6*10^9*Inputs!$D$54+C6*Sizing!$D$7*1024^3+Inputs!$D$72*1024^3),0) | G6: =IF(Inputs!$D$65>0,Inputs!$D$65,IF(Inputs!$D$69="continuous",IF(AND(Sizing!$D$30<=0,F6<=0),0,IF(F6<=0,Sizing!$D$30,IF(Sizing!$D$30<=0,F6,MIN(Sizing!$D$30,F6)))),Sizing!$D$29)) | H6: =IF(C6>0,Sizing!$D$26*Inputs!$D$62/(Sizing!$D$25+4*Inputs!$D$38*Inputs!$D$91*(Inputs!$D$21+(Inputs!$D$22-1)/2))/C6,0) | I6: =IF(Inputs!$D$28>0,Inputs!$D$28*10^9*Inputs!$D$63/(D6*10^9*Inputs!$D$54+C6*Sizing!$D$7*1024^3+Inputs!$D$72*1024^3),0) | J6: =IF(Inputs!$D$66>0,Inputs!$D$66,IF(AND(H6<=0,I6<=0),0,IF(I6<=0,H6,IF(H6<=0,I6,MIN(H6,I6)))))*Inputs!$D$68 | K6: =IF(AND(G6>0,J6>0),C6/(Sizing!$D$27/G6+Inputs!$D$22/J6),0) | L6: =Sizing!$D$12*K6 | M6: =IF(L6>0,CEILING(Inputs!$D$12*Inputs!$D$89*Inputs!$D$76/L6,1),0) | N6: =MAX(Sizing!$D$22,M6) | O6: =N6=B6
A7: 1 | B7: =N6 | C7: =IF(AND(Sizing!$D$12>0,B7>0),MIN(IF(Sizing!$D$15>0,Sizing!$D$15,10^9),MAX(1,CEILING(Inputs!$D$12/(Sizing!$D$12*B7),1))),1) | D7: =IF(Inputs!$D$52,Inputs!$D$48+Inputs!$D$49*(1-POWER(1-Inputs!$D$50/Inputs!$D$51,C7)),Inputs!$D$37) | E7: =IF(Inputs!$D$52,Inputs!$D$48+Inputs!$D$49*(1-POWER(1-Inputs!$D$50/Inputs!$D$51,C7+1)),Inputs!$D$37) | F7: =IF(AND(Inputs!$D$28>0,Inputs!$D$70>0),Inputs!$D$70*Inputs!$D$28*10^9*Inputs!$D$63/(E7*10^9*Inputs!$D$54+C7*Sizing!$D$7*1024^3+Inputs!$D$72*1024^3),0) | G7: =IF(Inputs!$D$65>0,Inputs!$D$65,IF(Inputs!$D$69="continuous",IF(AND(Sizing!$D$30<=0,F7<=0),0,IF(F7<=0,Sizing!$D$30,IF(Sizing!$D$30<=0,F7,MIN(Sizing!$D$30,F7)))),Sizing!$D$29)) | H7: =IF(C7>0,Sizing!$D$26*Inputs!$D$62/(Sizing!$D$25+4*Inputs!$D$38*Inputs!$D$91*(Inputs!$D$21+(Inputs!$D$22-1)/2))/C7,0) | I7: =IF(Inputs!$D$28>0,Inputs!$D$28*10^9*Inputs!$D$63/(D7*10^9*Inputs!$D$54+C7*Sizing!$D$7*1024^3+Inputs!$D$72*1024^3),0) | J7: =IF(Inputs!$D$66>0,Inputs!$D$66,IF(AND(H7<=0,I7<=0),0,IF(I7<=0,H7,IF(H7<=0,I7,MIN(H7,I7)))))*Inputs!$D$68 | K7: =IF(AND(G7>0,J7>0),C7/(Sizing!$D$27/G7+Inputs!$D$22/J7),0) | L7: =Sizing!$D$12*K7 | M7: =IF(L7>0,CEILING(Inputs!$D$12*Inputs!$D$89*Inputs!$D$76/L7,1),0) | N7: =MAX(Sizing!$D$22,M7) | O7: =N7=B7
A8: 2 | B8: =N7 | C8: =IF(AND(Sizing!$D$12>0,B8>0),MIN(IF(Sizing!$D$15>0,Sizing!$D$15,10^9),MAX(1,CEILING(Inputs!$D$12/(Sizing!$D$12*B8),1))),1) | D8: =IF(Inputs!$D$52,Inputs!$D$48+Inputs!$D$49*(1-POWER(1-Inputs!$D$50/Inputs!$D$51,C8)),Inputs!$D$37) | E8: =IF(Inputs!$D$52,Inputs!$D$48+Inputs!$D$49*(1-POWER(1-Inputs!$D$50/Inputs!$D$51,C8+1)),Inputs!$D$37) | F8: =IF(AND(Inputs!$D$28>0,Inputs!$D$70>0),Inputs!$D$70*Inputs!$D$28*10^9*Inputs!$D$63/(E8*10^9*Inputs!$D$54+C8*Sizing!$D$7*1024^3+Inputs!$D$72*1024^3),0) | G8: =IF(Inputs!$D$65>0,Inputs!$D$65,IF(Inputs!$D$69="continuous",IF(AND(Sizing!$D$30<=0,F8<=0),0,IF(F8<=0,Sizing!$D$30,IF(Sizing!$D$30<=0,F8,MIN(Sizing!$D$30,F8)))),Sizing!$D$29)) | H8: =IF(C8>0,Sizing!$D$26*Inputs!$D$62/(Sizing!$D$25+4*Inputs!$D$38*Inputs!$D$91*(Inputs!$D$21+(Inputs!$D$22-1)/2))/C8,0) | I8: =IF(Inputs!$D$28>0,Inputs!$D$28*10^9*Inputs!$D$63/(D8*10^9*Inputs!$D$54+C8*Sizing!$D$7*1024^3+Inputs!$D$72*1024^3),0) | J8: =IF(Inputs!$D$66>0,Inputs!$D$66,IF(AND(H8<=0,I8<=0),0,IF(I8<=0,H8,IF(H8<=0,I8,MIN(H8,I8)))))*Inputs!$D$68 | K8: =IF(AND(G8>0,J8>0),C8/(Sizing!$D$27/G8+Inputs!$D$22/J8),0) | L8: =Sizing!$D$12*K8 | M8: =IF(L8>0,CEILING(Inputs!$D$12*Inputs!$D$89*Inputs!$D$76/L8,1),0) | N8: =MAX(Sizing!$D$22,M8) | O8: =N8=B8
A9: 3 | B9: =N8 | C9: =IF(AND(Sizing!$D$12>0,B9>0),MIN(IF(Sizing!$D$15>0,Sizing!$D$15,10^9),MAX(1,CEILING(Inputs!$D$12/(Sizing!$D$12*B9),1))),1) | D9: =IF(Inputs!$D$52,Inputs!$D$48+Inputs!$D$49*(1-POWER(1-Inputs!$D$50/Inputs!$D$51,C9)),Inputs!$D$37) | E9: =IF(Inputs!$D$52,Inputs!$D$48+Inputs!$D$49*(1-POWER(1-Inputs!$D$50/Inputs!$D$51,C9+1)),Inputs!$D$37) | F9: =IF(AND(Inputs!$D$28>0,Inputs!$D$70>0),Inputs!$D$70*Inputs!$D$28*10^9*Inputs!$D$63/(E9*10^9*Inputs!$D$54+C9*Sizing!$D$7*1024^3+Inputs!$D$72*1024^3),0) | G9: =IF(Inputs!$D$65>0,Inputs!$D$65,IF(Inputs!$D$69="continuous",IF(AND(Sizing!$D$30<=0,F9<=0),0,IF(F9<=0,Sizing!$D$30,IF(Sizing!$D$30<=0,F9,MIN(Sizing!$D$30,F9)))),Sizing!$D$29)) | H9: =IF(C9>0,Sizing!$D$26*Inputs!$D$62/(Sizing!$D$25+4*Inputs!$D$38*Inputs!$D$91*(Inputs!$D$21+(Inputs!$D$22-1)/2))/C9,0) | I9: =IF(Inputs!$D$28>0,Inputs!$D$28*10^9*Inputs!$D$63/(D9*10^9*Inputs!$D$54+C9*Sizing!$D$7*1024^3+Inputs!$D$72*1024^3),0) | J9: =IF(Inputs!$D$66>0,Inputs!$D$66,IF(AND(H9<=0,I9<=0),0,IF(I9<=0,H9,IF(H9<=0,I9,MIN(H9,I9)))))*Inputs!$D$68 | K9: =IF(AND(G9>0,J9>0),C9/(Sizing!$D$27/G9+Inputs!$D$22/J9),0) | L9: =Sizing!$D$12*K9 | M9: =IF(L9>0,CEILING(Inputs!$D$12*Inputs!$D$89*Inputs!$D$76/L9,1),0) | N9: =MAX(Sizing!$D$22,M9) | O9: =N9=B9
A10: 4 | B10: =N9 | C10: =IF(AND(Sizing!$D$12>0,B10>0),MIN(IF(Sizing!$D$15>0,Sizing!$D$15,10^9),MAX(1,CEILING(Inputs!$D$12/(Sizing!$D$12*B10),1))),1) | D10: =IF(Inputs!$D$52,Inputs!$D$48+Inputs!$D$49*(1-POWER(1-Inputs!$D$50/Inputs!$D$51,C10)),Inputs!$D$37) | E10: =IF(Inputs!$D$52,Inputs!$D$48+Inputs!$D$49*(1-POWER(1-Inputs!$D$50/Inputs!$D$51,C10+1)),Inputs!$D$37) | F10: =IF(AND(Inputs!$D$28>0,Inputs!$D$70>0),Inputs!$D$70*Inputs!$D$28*10^9*Inputs!$D$63/(E10*10^9*Inputs!$D$54+C10*Sizing!$D$7*1024^3+Inputs!$D$72*1024^3),0) | G10: =IF(Inputs!$D$65>0,Inputs!$D$65,IF(Inputs!$D$69="continuous",IF(AND(Sizing!$D$30<=0,F10<=0),0,IF(F10<=0,Sizing!$D$30,IF(Sizing!$D$30<=0,F10,MIN(Sizing!$D$30,F10)))),Sizing!$D$29)) | H10: =IF(C10>0,Sizing!$D$26*Inputs!$D$62/(Sizing!$D$25+4*Inputs!$D$38*Inputs!$D$91*(Inputs!$D$21+(Inputs!$D$22-1)/2))/C10,0) | I10: =IF(Inputs!$D$28>0,Inputs!$D$28*10^9*Inputs!$D$63/(D10*10^9*Inputs!$D$54+C10*Sizing!$D$7*1024^3+Inputs!$D$72*1024^3),0) | J10: =IF(Inputs!$D$66>0,Inputs!$D$66,IF(AND(H10<=0,I10<=0),0,IF(I10<=0,H10,IF(H10<=0,I10,MIN(H10,I10)))))*Inputs!$D$68 | K10: =IF(AND(G10>0,J10>0),C10/(Sizing!$D$27/G10+Inputs!$D$22/J10),0) | L10: =Sizing!$D$12*K10 | M10: =IF(L10>0,CEILING(Inputs!$D$12*Inputs!$D$89*Inputs!$D$76/L10,1),0) | N10: =MAX(Sizing!$D$22,M10) | O10: =N10=B10
A11: 5 | B11: =N10 | C11: =IF(AND(Sizing!$D$12>0,B11>0),MIN(IF(Sizing!$D$15>0,Sizing!$D$15,10^9),MAX(1,CEILING(Inputs!$D$12/(Sizing!$D$12*B11),1))),1) | D11: =IF(Inputs!$D$52,Inputs!$D$48+Inputs!$D$49*(1-POWER(1-Inputs!$D$50/Inputs!$D$51,C11)),Inputs!$D$37) | E11: =IF(Inputs!$D$52,Inputs!$D$48+Inputs!$D$49*(1-POWER(1-Inputs!$D$50/Inputs!$D$51,C11+1)),Inputs!$D$37) | F11: =IF(AND(Inputs!$D$28>0,Inputs!$D$70>0),Inputs!$D$70*Inputs!$D$28*10^9*Inputs!$D$63/(E11*10^9*Inputs!$D$54+C11*Sizing!$D$7*1024^3+Inputs!$D$72*1024^3),0) | G11: =IF(Inputs!$D$65>0,Inputs!$D$65,IF(Inputs!$D$69="continuous",IF(AND(Sizing!$D$30<=0,F11<=0),0,IF(F11<=0,Sizing!$D$30,IF(Sizing!$D$30<=0,F11,MIN(Sizing!$D$30,F11)))),Sizing!$D$29)) | H11: =IF(C11>0,Sizing!$D$26*Inputs!$D$62/(Sizing!$D$25+4*Inputs!$D$38*Inputs!$D$91*(Inputs!$D$21+(Inputs!$D$22-1)/2))/C11,0) | I11: =IF(Inputs!$D$28>0,Inputs!$D$28*10^9*Inputs!$D$63/(D11*10^9*Inputs!$D$54+C11*Sizing!$D$7*1024^3+Inputs!$D$72*1024^3),0) | J11: =IF(Inputs!$D$66>0,Inputs!$D$66,IF(AND(H11<=0,I11<=0),0,IF(I11<=0,H11,IF(H11<=0,I11,MIN(H11,I11)))))*Inputs!$D$68 | K11: =IF(AND(G11>0,J11>0),C11/(Sizing!$D$27/G11+Inputs!$D$22/J11),0) | L11: =Sizing!$D$12*K11 | M11: =IF(L11>0,CEILING(Inputs!$D$12*Inputs!$D$89*Inputs!$D$76/L11,1),0) | N11: =MAX(Sizing!$D$22,M11) | O11: =N11=B11
A12: 6 | B12: =N11 | C12: =IF(AND(Sizing!$D$12>0,B12>0),MIN(IF(Sizing!$D$15>0,Sizing!$D$15,10^9),MAX(1,CEILING(Inputs!$D$12/(Sizing!$D$12*B12),1))),1) | D12: =IF(Inputs!$D$52,Inputs!$D$48+Inputs!$D$49*(1-POWER(1-Inputs!$D$50/Inputs!$D$51,C12)),Inputs!$D$37) | E12: =IF(Inputs!$D$52,Inputs!$D$48+Inputs!$D$49*(1-POWER(1-Inputs!$D$50/Inputs!$D$51,C12+1)),Inputs!$D$37) | F12: =IF(AND(Inputs!$D$28>0,Inputs!$D$70>0),Inputs!$D$70*Inputs!$D$28*10^9*Inputs!$D$63/(E12*10^9*Inputs!$D$54+C12*Sizing!$D$7*1024^3+Inputs!$D$72*1024^3),0) | G12: =IF(Inputs!$D$65>0,Inputs!$D$65,IF(Inputs!$D$69="continuous",IF(AND(Sizing!$D$30<=0,F12<=0),0,IF(F12<=0,Sizing!$D$30,IF(Sizing!$D$30<=0,F12,MIN(Sizing!$D$30,F12)))),Sizing!$D$29)) | H12: =IF(C12>0,Sizing!$D$26*Inputs!$D$62/(Sizing!$D$25+4*Inputs!$D$38*Inputs!$D$91*(Inputs!$D$21+(Inputs!$D$22-1)/2))/C12,0) | I12: =IF(Inputs!$D$28>0,Inputs!$D$28*10^9*Inputs!$D$63/(D12*10^9*Inputs!$D$54+C12*Sizing!$D$7*1024^3+Inputs!$D$72*1024^3),0) | J12: =IF(Inputs!$D$66>0,Inputs!$D$66,IF(AND(H12<=0,I12<=0),0,IF(I12<=0,H12,IF(H12<=0,I12,MIN(H12,I12)))))*Inputs!$D$68 | K12: =IF(AND(G12>0,J12>0),C12/(Sizing!$D$27/G12+Inputs!$D$22/J12),0) | L12: =Sizing!$D$12*K12 | M12: =IF(L12>0,CEILING(Inputs!$D$12*Inputs!$D$89*Inputs!$D$76/L12,1),0) | N12: =MAX(Sizing!$D$22,M12) | O12: =N12=B12
A13: 7 | B13: =N12 | C13: =IF(AND(Sizing!$D$12>0,B13>0),MIN(IF(Sizing!$D$15>0,Sizing!$D$15,10^9),MAX(1,CEILING(Inputs!$D$12/(Sizing!$D$12*B13),1))),1) | D13: =IF(Inputs!$D$52,Inputs!$D$48+Inputs!$D$49*(1-POWER(1-Inputs!$D$50/Inputs!$D$51,C13)),Inputs!$D$37) | E13: =IF(Inputs!$D$52,Inputs!$D$48+Inputs!$D$49*(1-POWER(1-Inputs!$D$50/Inputs!$D$51,C13+1)),Inputs!$D$37) | F13: =IF(AND(Inputs!$D$28>0,Inputs!$D$70>0),Inputs!$D$70*Inputs!$D$28*10^9*Inputs!$D$63/(E13*10^9*Inputs!$D$54+C13*Sizing!$D$7*1024^3+Inputs!$D$72*1024^3),0) | G13: =IF(Inputs!$D$65>0,Inputs!$D$65,IF(Inputs!$D$69="continuous",IF(AND(Sizing!$D$30<=0,F13<=0),0,IF(F13<=0,Sizing!$D$30,IF(Sizing!$D$30<=0,F13,MIN(Sizing!$D$30,F13)))),Sizing!$D$29)) | H13: =IF(C13>0,Sizing!$D$26*Inputs!$D$62/(Sizing!$D$25+4*Inputs!$D$38*Inputs!$D$91*(Inputs!$D$21+(Inputs!$D$22-1)/2))/C13,0) | I13: =IF(Inputs!$D$28>0,Inputs!$D$28*10^9*Inputs!$D$63/(D13*10^9*Inputs!$D$54+C13*Sizing!$D$7*1024^3+Inputs!$D$72*1024^3),0) | J13: =IF(Inputs!$D$66>0,Inputs!$D$66,IF(AND(H13<=0,I13<=0),0,IF(I13<=0,H13,IF(H13<=0,I13,MIN(H13,I13)))))*Inputs!$D$68 | K13: =IF(AND(G13>0,J13>0),C13/(Sizing!$D$27/G13+Inputs!$D$22/J13),0) | L13: =Sizing!$D$12*K13 | M13: =IF(L13>0,CEILING(Inputs!$D$12*Inputs!$D$89*Inputs!$D$76/L13,1),0) | N13: =MAX(Sizing!$D$22,M13) | O13: =N13=B13
A14: 8 | B14: =N13 | C14: =IF(AND(Sizing!$D$12>0,B14>0),MIN(IF(Sizing!$D$15>0,Sizing!$D$15,10^9),MAX(1,CEILING(Inputs!$D$12/(Sizing!$D$12*B14),1))),1) | D14: =IF(Inputs!$D$52,Inputs!$D$48+Inputs!$D$49*(1-POWER(1-Inputs!$D$50/Inputs!$D$51,C14)),Inputs!$D$37) | E14: =IF(Inputs!$D$52,Inputs!$D$48+Inputs!$D$49*(1-POWER(1-Inputs!$D$50/Inputs!$D$51,C14+1)),Inputs!$D$37) | F14: =IF(AND(Inputs!$D$28>0,Inputs!$D$70>0),Inputs!$D$70*Inputs!$D$28*10^9*Inputs!$D$63/(E14*10^9*Inputs!$D$54+C14*Sizing!$D$7*1024^3+Inputs!$D$72*1024^3),0) | G14: =IF(Inputs!$D$65>0,Inputs!$D$65,IF(Inputs!$D$69="continuous",IF(AND(Sizing!$D$30<=0,F14<=0),0,IF(F14<=0,Sizing!$D$30,IF(Sizing!$D$30<=0,F14,MIN(Sizing!$D$30,F14)))),Sizing!$D$29)) | H14: =IF(C14>0,Sizing!$D$26*Inputs!$D$62/(Sizing!$D$25+4*Inputs!$D$38*Inputs!$D$91*(Inputs!$D$21+(Inputs!$D$22-1)/2))/C14,0) | I14: =IF(Inputs!$D$28>0,Inputs!$D$28*10^9*Inputs!$D$63/(D14*10^9*Inputs!$D$54+C14*Sizing!$D$7*1024^3+Inputs!$D$72*1024^3),0) | J14: =IF(Inputs!$D$66>0,Inputs!$D$66,IF(AND(H14<=0,I14<=0),0,IF(I14<=0,H14,IF(H14<=0,I14,MIN(H14,I14)))))*Inputs!$D$68 | K14: =IF(AND(G14>0,J14>0),C14/(Sizing!$D$27/G14+Inputs!$D$22/J14),0) | L14: =Sizing!$D$12*K14 | M14: =IF(L14>0,CEILING(Inputs!$D$12*Inputs!$D$89*Inputs!$D$76/L14,1),0) | N14: =MAX(Sizing!$D$22,M14) | O14: =N14=B14
A15: 9 | B15: =N14 | C15: =IF(AND(Sizing!$D$12>0,B15>0),MIN(IF(Sizing!$D$15>0,Sizing!$D$15,10^9),MAX(1,CEILING(Inputs!$D$12/(Sizing!$D$12*B15),1))),1) | D15: =IF(Inputs!$D$52,Inputs!$D$48+Inputs!$D$49*(1-POWER(1-Inputs!$D$50/Inputs!$D$51,C15)),Inputs!$D$37) | E15: =IF(Inputs!$D$52,Inputs!$D$48+Inputs!$D$49*(1-POWER(1-Inputs!$D$50/Inputs!$D$51,C15+1)),Inputs!$D$37) | F15: =IF(AND(Inputs!$D$28>0,Inputs!$D$70>0),Inputs!$D$70*Inputs!$D$28*10^9*Inputs!$D$63/(E15*10^9*Inputs!$D$54+C15*Sizing!$D$7*1024^3+Inputs!$D$72*1024^3),0) | G15: =IF(Inputs!$D$65>0,Inputs!$D$65,IF(Inputs!$D$69="continuous",IF(AND(Sizing!$D$30<=0,F15<=0),0,IF(F15<=0,Sizing!$D$30,IF(Sizing!$D$30<=0,F15,MIN(Sizing!$D$30,F15)))),Sizing!$D$29)) | H15: =IF(C15>0,Sizing!$D$26*Inputs!$D$62/(Sizing!$D$25+4*Inputs!$D$38*Inputs!$D$91*(Inputs!$D$21+(Inputs!$D$22-1)/2))/C15,0) | I15: =IF(Inputs!$D$28>0,Inputs!$D$28*10^9*Inputs!$D$63/(D15*10^9*Inputs!$D$54+C15*Sizing!$D$7*1024^3+Inputs!$D$72*1024^3),0) | J15: =IF(Inputs!$D$66>0,Inputs!$D$66,IF(AND(H15<=0,I15<=0),0,IF(I15<=0,H15,IF(H15<=0,I15,MIN(H15,I15)))))*Inputs!$D$68 | K15: =IF(AND(G15>0,J15>0),C15/(Sizing!$D$27/G15+Inputs!$D$22/J15),0) | L15: =Sizing!$D$12*K15 | M15: =IF(L15>0,CEILING(Inputs!$D$12*Inputs!$D$89*Inputs!$D$76/L15,1),0) | N15: =MAX(Sizing!$D$22,M15) | O15: =N15=B15
A16: 10 | B16: =N15 | C16: =IF(AND(Sizing!$D$12>0,B16>0),MIN(IF(Sizing!$D$15>0,Sizing!$D$15,10^9),MAX(1,CEILING(Inputs!$D$12/(Sizing!$D$12*B16),1))),1) | D16: =IF(Inputs!$D$52,Inputs!$D$48+Inputs!$D$49*(1-POWER(1-Inputs!$D$50/Inputs!$D$51,C16)),Inputs!$D$37) | E16: =IF(Inputs!$D$52,Inputs!$D$48+Inputs!$D$49*(1-POWER(1-Inputs!$D$50/Inputs!$D$51,C16+1)),Inputs!$D$37) | F16: =IF(AND(Inputs!$D$28>0,Inputs!$D$70>0),Inputs!$D$70*Inputs!$D$28*10^9*Inputs!$D$63/(E16*10^9*Inputs!$D$54+C16*Sizing!$D$7*1024^3+Inputs!$D$72*1024^3),0) | G16: =IF(Inputs!$D$65>0,Inputs!$D$65,IF(Inputs!$D$69="continuous",IF(AND(Sizing!$D$30<=0,F16<=0),0,IF(F16<=0,Sizing!$D$30,IF(Sizing!$D$30<=0,F16,MIN(Sizing!$D$30,F16)))),Sizing!$D$29)) | H16: =IF(C16>0,Sizing!$D$26*Inputs!$D$62/(Sizing!$D$25+4*Inputs!$D$38*Inputs!$D$91*(Inputs!$D$21+(Inputs!$D$22-1)/2))/C16,0) | I16: =IF(Inputs!$D$28>0,Inputs!$D$28*10^9*Inputs!$D$63/(D16*10^9*Inputs!$D$54+C16*Sizing!$D$7*1024^3+Inputs!$D$72*1024^3),0) | J16: =IF(Inputs!$D$66>0,Inputs!$D$66,IF(AND(H16<=0,I16<=0),0,IF(I16<=0,H16,IF(H16<=0,I16,MIN(H16,I16)))))*Inputs!$D$68 | K16: =IF(AND(G16>0,J16>0),C16/(Sizing!$D$27/G16+Inputs!$D$22/J16),0) | L16: =Sizing!$D$12*K16 | M16: =IF(L16>0,CEILING(Inputs!$D$12*Inputs!$D$89*Inputs!$D$76/L16,1),0) | N16: =MAX(Sizing!$D$22,M16) | O16: =N16=B16
A17: 11 | B17: =N16 | C17: =IF(AND(Sizing!$D$12>0,B17>0),MIN(IF(Sizing!$D$15>0,Sizing!$D$15,10^9),MAX(1,CEILING(Inputs!$D$12/(Sizing!$D$12*B17),1))),1) | D17: =IF(Inputs!$D$52,Inputs!$D$48+Inputs!$D$49*(1-POWER(1-Inputs!$D$50/Inputs!$D$51,C17)),Inputs!$D$37) | E17: =IF(Inputs!$D$52,Inputs!$D$48+Inputs!$D$49*(1-POWER(1-Inputs!$D$50/Inputs!$D$51,C17+1)),Inputs!$D$37) | F17: =IF(AND(Inputs!$D$28>0,Inputs!$D$70>0),Inputs!$D$70*Inputs!$D$28*10^9*Inputs!$D$63/(E17*10^9*Inputs!$D$54+C17*Sizing!$D$7*1024^3+Inputs!$D$72*1024^3),0) | G17: =IF(Inputs!$D$65>0,Inputs!$D$65,IF(Inputs!$D$69="continuous",IF(AND(Sizing!$D$30<=0,F17<=0),0,IF(F17<=0,Sizing!$D$30,IF(Sizing!$D$30<=0,F17,MIN(Sizing!$D$30,F17)))),Sizing!$D$29)) | H17: =IF(C17>0,Sizing!$D$26*Inputs!$D$62/(Sizing!$D$25+4*Inputs!$D$38*Inputs!$D$91*(Inputs!$D$21+(Inputs!$D$22-1)/2))/C17,0) | I17: =IF(Inputs!$D$28>0,Inputs!$D$28*10^9*Inputs!$D$63/(D17*10^9*Inputs!$D$54+C17*Sizing!$D$7*1024^3+Inputs!$D$72*1024^3),0) | J17: =IF(Inputs!$D$66>0,Inputs!$D$66,IF(AND(H17<=0,I17<=0),0,IF(I17<=0,H17,IF(H17<=0,I17,MIN(H17,I17)))))*Inputs!$D$68 | K17: =IF(AND(G17>0,J17>0),C17/(Sizing!$D$27/G17+Inputs!$D$22/J17),0) | L17: =Sizing!$D$12*K17 | M17: =IF(L17>0,CEILING(Inputs!$D$12*Inputs!$D$89*Inputs!$D$76/L17,1),0) | N17: =MAX(Sizing!$D$22,M17) | O17: =N17=B17
A18: 12 | B18: =N17 | C18: =IF(AND(Sizing!$D$12>0,B18>0),MIN(IF(Sizing!$D$15>0,Sizing!$D$15,10^9),MAX(1,CEILING(Inputs!$D$12/(Sizing!$D$12*B18),1))),1) | D18: =IF(Inputs!$D$52,Inputs!$D$48+Inputs!$D$49*(1-POWER(1-Inputs!$D$50/Inputs!$D$51,C18)),Inputs!$D$37) | E18: =IF(Inputs!$D$52,Inputs!$D$48+Inputs!$D$49*(1-POWER(1-Inputs!$D$50/Inputs!$D$51,C18+1)),Inputs!$D$37) | F18: =IF(AND(Inputs!$D$28>0,Inputs!$D$70>0),Inputs!$D$70*Inputs!$D$28*10^9*Inputs!$D$63/(E18*10^9*Inputs!$D$54+C18*Sizing!$D$7*1024^3+Inputs!$D$72*1024^3),0) | G18: =IF(Inputs!$D$65>0,Inputs!$D$65,IF(Inputs!$D$69="continuous",IF(AND(Sizing!$D$30<=0,F18<=0),0,IF(F18<=0,Sizing!$D$30,IF(Sizing!$D$30<=0,F18,MIN(Sizing!$D$30,F18)))),Sizing!$D$29)) | H18: =IF(C18>0,Sizing!$D$26*Inputs!$D$62/(Sizing!$D$25+4*Inputs!$D$38*Inputs!$D$91*(Inputs!$D$21+(Inputs!$D$22-1)/2))/C18,0) | I18: =IF(Inputs!$D$28>0,Inputs!$D$28*10^9*Inputs!$D$63/(D18*10^9*Inputs!$D$54+C18*Sizing!$D$7*1024^3+Inputs!$D$72*1024^3),0) | J18: =IF(Inputs!$D$66>0,Inputs!$D$66,IF(AND(H18<=0,I18<=0),0,IF(I18<=0,H18,IF(H18<=0,I18,MIN(H18,I18)))))*Inputs!$D$68 | K18: =IF(AND(G18>0,J18>0),C18/(Sizing!$D$27/G18+Inputs!$D$22/J18),0) | L18: =Sizing!$D$12*K18 | M18: =IF(L18>0,CEILING(Inputs!$D$12*Inputs!$D$89*Inputs!$D$76/L18,1),0) | N18: =MAX(Sizing!$D$22,M18) | O18: =N18=B18
... A25: 19 | B25: =N24 | C25: =IF(AND(Sizing!$D$12>0,B25>0),MIN(IF(Sizing!$D$15>0,Sizing!$D$15,10^9),MAX(1,CEILING(Inputs!$D$12/(Sizing!$D$12*B25),1))),1) | D25: =IF(Inputs!$D$52,Inputs!$D$48+Inputs!$D$49*(1-POWER(1-Inputs!$D$50/Inputs!$D$51,C25)),Inputs!$D$37) | E25: =IF(Inputs!$D$52,Inputs!$D$48+Inputs!$D$49*(1-POWER(1-Inputs!$D$50/Inputs!$D$51,C25+1)),Inputs!$D$37) | F25: =IF(AND(Inputs!$D$28>0,Inputs!$D$70>0),Inputs!$D$70*Inputs!$D$28*10^9*Inputs!$D$63/(E25*10^9*Inputs!$D$54+C25*Sizing!$D$7*1024^3+Inputs!$D$72*1024^3),0) | G25: =IF(Inputs!$D$65>0,Inputs!$D$65,IF(Inputs!$D$69="continuous",IF(AND(Sizing!$D$30<=0,F25<=0),0,IF(F25<=0,Sizing!$D$30,IF(Sizing!$D$30<=0,F25,MIN(Sizing!$D$30,F25)))),Sizing!$D$29)) | H25: =IF(C25>0,Sizing!$D$26*Inputs!$D$62/(Sizing!$D$25+4*Inputs!$D$38*Inputs!$D$91*(Inputs!$D$21+(Inputs!$D$22-1)/2))/C25,0) | I25: =IF(Inputs!$D$28>0,Inputs!$D$28*10^9*Inputs!$D$63/(D25*10^9*Inputs!$D$54+C25*Sizing!$D$7*1024^3+Inputs!$D$72*1024^3),0) | J25: =IF(Inputs!$D$66>0,Inputs!$D$66,IF(AND(H25<=0,I25<=0),0,IF(I25<=0,H25,IF(H25<=0,I25,MIN(H25,I25)))))*Inputs!$D$68 | K25: =IF(AND(G25>0,J25>0),C25/(Sizing!$D$27/G25+Inputs!$D$22/J25),0) | L25: =Sizing!$D$12*K25 | M25: =IF(L25>0,CEILING(Inputs!$D$12*Inputs!$D$89*Inputs!$D$76/L25,1),0) | N25: =MAX(Sizing!$D$22,M25) | O25: =N25=B25
A28: Статус сходимости | B28: =IF(ISNUMBER(MATCH(TRUE(),O6:O25,0)),"converged",IF(N30<=B30,"oscillating","not_converged"))
A29: Кандидат без сходимости: max(Servers^(20), Servers^(19)); самосогласован, если max(Servers_mem, Servers^comp(кандидат)) ≤ кандидат | B29: =IFERROR(MATCH(TRUE(),O6:O25,0),20)
A30: кандидат | B30: =MAX(N25,B25) | C30: =IF(AND(Sizing!$D$12>0,B30>0),MIN(IF(Sizing!$D$15>0,Sizing!$D$15,10^9),MAX(1,CEILING(Inputs!$D$12/(Sizing!$D$12*B30),1))),1) | D30: =IF(Inputs!$D$52,Inputs!$D$48+Inputs!$D$49*(1-POWER(1-Inputs!$D$50/Inputs!$D$51,C30)),Inputs!$D$37) | E30: =IF(Inputs!$D$52,Inputs!$D$48+Inputs!$D$49*(1-POWER(1-Inputs!$D$50/Inputs!$D$51,C30+1)),Inputs!$D$37) | F30: =IF(AND(Inputs!$D$28>0,Inputs!$D$70>0),Inputs!$D$70*Inputs!$D$28*10^9*Inputs!$D$63/(E30*10^9*Inputs!$D$54+C30*Sizing!$D$7*1024^3+Inputs!$D$72*1024^3),0) | G30: =IF(Inputs!$D$65>0,Inputs!$D$65,IF(Inputs!$D$69="continuous",IF(AND(Sizing!$D$30<=0,F30<=0),0,IF(F30<=0,Sizing!$D$30,IF(Sizing!$D$30<=0,F30,MIN(Sizing!$D$30,F30)))),Sizing!$D$29)) | H30: =IF(C30>0,Sizing!$D$26*Inputs!$D$62/(Sizing!$D$25+4*Inputs!$D$38*Inputs!$D$91*(Inputs!$D$21+(Inputs!$D$22-1)/2))/C30,0) | I30: =IF(Inputs!$D$28>0,Inputs!$D$28*10^9*Inputs!$D$63/(D30*10^9*Inputs!$D$54+C30*Sizing!$D$7*1024^3+Inputs!$D$72*1024^3),0) | J30: =IF(Inputs!$D$66>0,Inputs!$D$66,IF(AND(H30<=0,I30<=0),0,IF(I30<=0,H30,IF(H30<=0,I30,MIN(H30,I30)))))*Inputs!$D$68 | K30: =IF(AND(G30>0,J30>0),C30/(Sizing!$D$27/G30+Inputs!$D$22/J30),0) | L30: =Sizing!$D$12*K30 | M30: =IF(L30>0,CEILING(Inputs!$D$12*Inputs!$D$89*Inputs!$D$76/L30,1),0) | N30: =MAX(Sizing!$D$22,M30) | O30: =N30=B30
A32: Итоговые состояния
A33: S* (сошедшееся) | B33: =IF(B28="converged",INDEX(B6:B25,B29),IF(B28="oscillating",B30,MAX(B30,N30))) | C33: =IF(AND(Sizing!$D$12>0,B33>0),MIN(IF(Sizing!$D$15>0,Sizing!$D$15,10^9),MAX(1,CEILING(Inputs!$D$12/(Sizing!$D$12*B33),1))),1) | D33: =IF(Inputs!$D$52,Inputs!$D$48+Inputs!$D$49*(1-POWER(1-Inputs!$D$50/Inputs!$D$51,C33)),Inputs!$D$37) | E33: =IF(Inputs!$D$52,Inputs!$D$48+Inputs!$D$49*(1-POWER(1-Inputs!$D$50/Inputs!$D$51,C33+1)),Inputs!$D$37) | F33: =IF(AND(Inputs!$D$28>0,Inputs!$D$70>0),Inputs!$D$70*Inputs!$D$28*10^9*Inputs!$D$63/(E33*10^9*Inputs!$D$54+C33*Sizing!$D$7*1024^3+Inputs!$D$72*1024^3),0) | G33: =IF(Inputs!$D$65>0,Inputs!$D$65,IF(Inputs!$D$69="continuous",IF(AND(Sizing!$D$30<=0,F33<=0),0,IF(F33<=0,Sizing!$D$30,IF(Sizing!$D$30<=0,F33,MIN(Sizing!$D$30,F33)))),Sizing!$D$29)) | H33: =IF(C33>0,Sizing!$D$26*Inputs!$D$62/(Sizing!$D$25+4*Inputs!$D$38*Inputs!$D$91*(Inputs!$D$21+(Inputs!$D$22-1)/2))/C33,0) | I33: =IF(Inputs!$D$28>0,Inputs!$D$28*10^9*Inputs!$D$63/(D33*10^9*Inputs!$D$54+C33*Sizing!$D$7*1024^3+Inputs!$D$72*1024^3),0) | J33: =IF(Inputs!$D$66>0,Inputs!$D$66,IF(AND(H33<=0,I33<=0),0,IF(I33<=0,H33,IF(H33<=0,I33,MIN(H33,I33)))))*Inputs!$D$68 | K33: =IF(AND(G33>0,J33>0),C33/(Sizing!$D$27/G33+Inputs!$D$22/J33),0) | L33: =Sizing!$D$12*K33 | M33: =IF(L33>0,CEILING(Inputs!$D$12*Inputs!$D$89*Inputs!$D$76/L33,1),0) | N33: =MAX(Sizing!$D$22,M33) | O33: =N33=B33
A34: BS = 1 (ненагруженный) | B34: =B33 | C34: =1 | D34: =IF(Inputs!$D$52,Inputs!$D$48+Inputs!$D$49*(1-POWER(1-Inputs!$D$50/Inputs!$D$51,C34)),Inputs!$D$37) | E34: =IF(Inputs!$D$52,Inputs!$D$48+Inputs!$D$49*(1-POWER(1-Inputs!$D$50/Inputs!$D$51,C34+1)),Inputs!$D$37) | F34: =IF(AND(Inputs!$D$28>0,Inputs!$D$70>0),Inputs!$D$70*Inputs!$D$28*10^9*Inputs!$D$63/(E34*10^9*Inputs!$D$54+C34*Sizing!$D$7*1024^3+Inputs!$D$72*1024^3),0) | G34: =IF(Inputs!$D$65>0,Inputs!$D$65,IF(Inputs!$D$69="continuous",IF(AND(Sizing!$D$30<=0,F34<=0),0,IF(F34<=0,Sizing!$D$30,IF(Sizing!$D$30<=0,F34,MIN(Sizing!$D$30,F34)))),Sizing!$D$29)) | H34: =IF(C34>0,Sizing!$D$26*Inputs!$D$62/(Sizing!$D$25+4*Inputs!$D$38*Inputs!$D$91*(Inputs!$D$21+(Inputs!$D$22-1)/2))/C34,0) | I34: =IF(Inputs!$D$28>0,Inputs!$D$28*10^9*Inputs!$D$63/(D34*10^9*Inputs!$D$54+C34*Sizing!$D$7*1024^3+Inputs!$D$72*1024^3),0) | J34: =IF(Inputs!$D$66>0,Inputs!$D$66,IF(AND(H34<=0,I34<=0),0,IF(I34<=0,H34,IF(H34<=0,I34,MIN(H34,I34)))))*Inputs!$D$68 | K34: =IF(AND(G34>0,J34>0),C34/(Sizing!$D$27/G34+Inputs!$D$22/J34),0) | L34: =Sizing!$D$12*K34 | M34: =IF(L34>0,CEILING(Inputs!$D$12*Inputs!$D$89*Inputs!$D$76/L34,1),0) | N34: =MAX(Sizing!$D$22,M34) | O34: =N34=B34
A35: Servers_final (с override) | B35: =Sizing!$D$68 | C35: =IF(AND(Sizing!$D$12>0,B35>0),MIN(IF(Sizing!$D$15>0,Sizing!$D$15,10^9),MAX(1,CEILING(Inputs!$D$12/(Sizing!$D$12*B35),1))),1) | D35: =IF(Inputs!$D$52,Inputs!$D$48+Inputs!$D$49*(1-POWER(1-Inputs!$D$50/Inputs!$D$51,C35)),Inputs!$D$37) | E35: =IF(Inputs!$D$52,Inputs!$D$48+Inputs!$D$49*(1-POWER(1-Inputs!$D$50/Inputs!$D$51,C35+1)),Inputs!$D$37) | F35: =IF(AND(Inputs!$D$28>0,Inputs!$D$70>0),Inputs!$D$70*Inputs!$D$28*10^9*Inputs!$D$63/(E35*10^9*Inputs!$D$54+C35*Sizing!$D$7*1024^3+Inputs!$D$72*1024^3),0) | G35: =IF(Inputs!$D$65>0,Inputs!$D$65,IF(Inputs!$D$69="continuous",IF(AND(Sizing!$D$30<=0,F35<=0),0,IF(F35<=0,Sizing!$D$30,IF(Sizing!$D$30<=0,F35,MIN(Sizing!$D$30,F35)))),Sizing!$D$29)) | H35: =IF(C35>0,Sizing!$D$26*Inputs!$D$62/(Sizing!$D$25+4*Inputs!$D$38*Inputs!$D$91*(Inputs!$D$21+(Inputs!$D$22-1)/2))/C35,0) | I35: =IF(Inputs!$D$28>0,Inputs!$D$28*10^9*Inputs!$D$63/(D35*10^9*Inputs!$D$54+C35*Sizing!$D$7*1024^3+Inputs!$D$72*1024^3),0) | J35: =IF(Inputs!$D$66>0,Inputs!$D$66,IF(AND(H35<=0,I35<=0),0,IF(I35<=0,H35,IF(H35<=0,I35,MIN(H35,I35)))))*Inputs!$D$68 | K35: =IF(AND(G35>0,J35>0),C35/(Sizing!$D$27/G35+Inputs!$D$22/J35),0) | L35: =Sizing!$D$12*K35 | M35: =IF(L35>0,CEILING(Inputs!$D$12*Inputs!$D$89*Inputs!$D$76/L35,1),0) | N35: =MAX(Sizing!$D$22,M35) | O35: =N35=B35

Sheet Agentic
A1: Агентные архитектуры — учёт K_calls, RAG, tool-use (Прил. В)
A2: Ввод (INPUT) | B2: Расчёт / Итог (bold) | C2: → перенос в Inputs
A4: Расширение базовой токеновой модели для агентных сценариев (ReAct, RAG, CoT, multi-agent). Лист рассчитывает ЭФФЕКТИВНЫЕ параметры при K_calls > 1.
A5: 📋 Как пользоваться этим листом
A6: 1. Заполните 5 синих (INPUT) ячеек ниже — параметры агентной архитектуры.
A7: 2. Калькулятор вычислит ЭФФЕКТИВНЫЕ значения SP_eff, Prp_eff, A_eff, MRT_eff, R_eff.
A8: 3. Перенесите 5 ЭФФЕКТИВНЫХ значений обратно в Inputs (заменят исходные):
A9: • SP_eff → Inputs!SP (системный промпт, увеличенный на SP_tools)
A10: • Prp_eff → Inputs!Prp (запрос, увеличенный на C_rag)
A11: • A_eff → Inputs!A (ответ, увеличенный на A_tool)
A12: • MRT_eff → Inputs!MRT (reasoning — max(MRT, reason_MRT))
A13: • R_eff → Inputs!R (частота запросов, умноженная на K_calls)
A14: 4. Пересчитайте сайзинг — учёт агентной нагрузки применится автоматически:
A15: SL_raw = SP_eff + N_prp · (Prp_eff + MRT_eff + A_eff) вычислится на листе Inputs.
... A22: Архитектурный паттерн (Приложение В.6)
A23: K_calls (LLM-вызовов на запрос) | B23: Single-turn=1; RAG=1-2; ReAct=3-10; Multi-agent=6-20+ | C23: INPUT | D23: 1 | E23: pcs
A24: SP_tools (токенов на tool definitions) | B24: 0-500 для простых; 500-2000 для ReAct; 1-3K для coding-agent | C24: INPUT | D24: 0 | E24: tokens
A25: C_rag (токенов RAG-контекста на вызов) | B25: 0; RAG: 1-5K; Agentic RAG: 1-5K × N_поисков | C25: INPUT | D25: 0 | E25: tokens
A26: A_tool (токенов tool_call JSON в ответе) | B26: 50-200 для function-calling, 200-500 для coding | C26: INPUT | D26: 0 | E26: tokens
A27: MRT для reasoning-моделей | B27: o1/R1: 8-25K thinking tokens на запрос | C27: INPUT | D27: 0 | E27: tokens
A29: Эффективные параметры (В.1-В.4)
A30: SP_eff = SP + SP_tools | B30: Увеличенный системный промпт | C30: calc | D30: =Inputs!D15+D24 | E30: tokens
A31: Prp_eff = Prp + C_rag | B31: Запрос с RAG-контекстом | C31: calc | D31: =Inputs!D16+D25 | E31: tokens
A32: A_eff = A + A_tool | B32: Ответ с tool_call JSON | C32: calc | D32: =Inputs!D17+D26 | E32: tokens
A33: MRT_eff = max(MRT, reason_MRT) | B33: Берётся больший из базового и reasoning | C33: calc | D33: =MAX(Inputs!D18,D27) | E33: tokens
A34: TS_agent (полная длина сессии, В.4) | B34: TS = SL_pf^raw + T_dec (Inputs!D20, §2.2) | C34: calc | D34: =Inputs!D20 | E34: tokens
A35: SL_peak (пик ОДНОГО вызова — для KV) | B35: SL_pf после окна (Inputs!D21) | C35: calc | D35: =Inputs!D21 | E35: tokens
A36: T_in_total (совокупные токены за n вызовов) | B36: n·C_sys + n(n-1)/2·s — для биллинга, не для KV | C36: calc | D36: =D23*D30+D23*(D23-1)/2*D32 | E36: tokens
A38: 🎯 Куда применить: 5 значений для переноса в Inputs
A39: SP_eff → перенести в Inputs!SP | B39: Учитывается автоматически в Inputs (блок 2.3): D15+SP_tools | C39: calc | D39: =D30 | E39: tokens
A40: Prp_eff → перенести в Inputs!Prp | B40: Учитывается автоматически в Inputs (блок 2.3): D16+C_rag | C40: calc | D40: =D31 | E40: tokens
A41: A_eff → перенести в Inputs!A | B41: Учитывается автоматически в Inputs (блок 2.3): D17+A_tool | C41: calc | D41: =D32 | E41: tokens
A42: MRT_eff → перенести в Inputs!MRT | B42: Учитывается автоматически в Inputs (блок 2.3): MRT | C42: calc | D42: =D33 | E42: tokens
A43: R_eff → перенести в Inputs!R | B43: R_eff = R · K_calls — учитывается автоматически (Inputs!D89) | C43: calc | D43: =Inputs!D75*D23 | E43: req/s
A45: 📎 Справочно (не переносится в Inputs)
A46: SL_peak (пик контекста одного вызова) | B46: SL_pf после окна, учитывается автоматически | C46: calc | D46: =Inputs!D21 | E46: tokens
A47: TS_agent (полная длина сессии) | B47: Оценка стоимости сессии — для биллинга и capacity planning | C47: calc | D47: =D34 | E47: tokens
A48: ⚠️ ВАЖНО: пока вы не перенесёте 5 значений (SP_eff, Prp_eff, A_eff, MRT_eff, R_eff) в Inputs, основной расчёт НЕ учитывает агентную нагрузку!
A50: Пример применения
A51: Допустим, у вас ReAct-агент: K_calls=5, SP_tools=1500, C_rag=2000, A_tool=150, reason_MRT=0.
...

Sheet Calibration
A1: Калибровка η_mem, η_pf, η_dec — Приложение Е методики
A2: Ввод (INPUT) | B2: Расчёт / Итог (bold) | C2: Проверка ✓/✗ — окрашивается по результату
A4: Введите наблюдаемые значения пропускной способности из двух нагрузочных прогонов EvalScope (decode-heavy и prefill-heavy). Калькулятор вычислит калибровочные коэффициенты, которые можно использовать в Inputs.
A6: Decode-heavy прогон (короткий prompt, длинный output)
A7: BS (--parallel) | B7: Число параллельных сессий в прогоне | C7: INPUT | D7: 30 | E7: -
A8: Th_dec^observed | B8: Output token throughput из EvalScope | C8: INPUT | D8: 2000 | E8: tok/s
A9: SL прогона (средний prompt) | B9: min-prompt-length ≈ 400-600 | C9: INPUT | D9: 500 | E9: tokens
A10: T_dec прогона (средний output) | B10: min-tokens ≈ 300-400 для decode-heavy | C10: INPUT | D10: 400 | E10: tokens
A11: M_KV для прогона (на сессию) | B11: M_KV под SL прогона = prompt + output; MLA: L·(r + rope)·SL·B_state | C11: calc | D11: =IF(Inputs!D47,Inputs!D38*(Inputs!D45+Inputs!D46)*(D9+D10)*Inputs!D55*Inputs!D57/1024^3,2*Inputs!D38*Inputs!D41*Inputs!D42*(D9+D10)*Inputs!D55*Inputs!D57/1024^3) | E11: GiB
A12: η_mem (выведено из прогона) | B12: Е.2: η_mem = Th₁/(N·BS) · (P_eff(BS)·10⁹·B_q + BS·M_KV·1024³ + O_fixed·1024³) / (BW·10⁹) | C12: calc | D12: =IF(AND(D7>0,Inputs!D28>0,Sizing!D12>0),D8*(IF(Inputs!D52,(Inputs!D48+Inputs!D49*(1-POWER(1-Inputs!D50/Inputs!D51,D7))),Inputs!D37)*10^9*Inputs!D54+D7*D11*1024^3+Inputs!D72*1024^3)/(Inputs!D28*10^9*D7*Sizing!D12),0) | E12: -
A13: η_dec (выведено из прогона) | B13: Е.3: η_dec = Th_dec^obs · (FPS + 4·L·d_attn^dec·(SL + (T−1)/2)) / (F_count · N). Без множителя BS; валиден только при compute-bound decode. | C13: calc | D13: =IF(AND(Sizing!D26>0,Sizing!D12>0),D8*(Sizing!D25+4*Inputs!D38*Inputs!D91*(D9+(D10-1)/2))/(Sizing!D26*Sizing!D12),0) | E13: -
A14: Узкое место decode (по двум прогонам) | B14: Е.3: по одному прогону bottleneck не определяется. Сравните прогоны 1 и 2: aggregate Th_dec растёт ~∝ BS → memory-bound (калибруйте η_mem); почти не растёт → compute-bound (η_dec валиден). | C14: calc | D14: =IF(AND(D7>0,D18>0,D8>0,D19>0,D7<>D18),IF(LN(MAX(D8,D19)/MIN(D8,D19))/LN(MAX(D7,D18)/MIN(D7,D18))>=0.5,"memory-bound: используйте η_mem; η_dec не калибруется","compute-bound: η_dec валиден"),"нужен второй прогон с другим BS") | E14: status
A16: Калибровка O_fixed (опц., 2-точечный прогон — для MoE / FP8)
A17: Введите данные ВТОРОГО decode-heavy прогона (на другом BS, с теми же SL и T_dec, что и в верхнем прогоне). Формула решает систему 2-х уравнений и даёт O_fixed и η_core (оба параметра новой формулы §6.2 H-6). Для dense BF16 моделей обычно O_fixed ≈ 0 (nan тут же оставьте формулу неактивной). Для MoE + FP8 на H100 vLLM типично: O_fixed = 8-10 GB.
A18: BS₂ (--parallel, 2-й прогон) | B18: Должен ЗНАЧИТЕЛЬНО отличаться от BS первого прогона (в 4-20× раз); SL и T_dec — те же. | C18: INPUT | D18: 1 | E18: -
A19: Th_dec^observed (2-й прогон) | B19: Output token throughput из EvalScope (aggregate). | C19: INPUT | D19: 100 | E19: tok/s
A20: D₁ = P_eff(BS₁)·B_q·10⁹ + BS₁·M_kv·1024³ | B20: Знаменатель Th_dec для прогона 1 (без O_fixed). Примечание: p_eff_expr уже содержит *10⁹, поэтому здесь только *B_quant. | C20: calc | D20: =IF(Inputs!D52,(Inputs!D48+Inputs!D49*(1-POWER(1-Inputs!D50/Inputs!D51,D7))),Inputs!D37)*10^9*Inputs!D54+D7*D11*1024^3 | E20: bytes
A21: D₂ = P_eff(BS₂)·B_q·10⁹ + BS₂·M_kv·1024³ | B21: Знаменатель Th_dec для прогона 2 (без O_fixed); M_kv одинаковое (общая SL) | C21: calc | D21: =IF(Inputs!D52,(Inputs!D48+Inputs!D49*(1-POWER(1-Inputs!D50/Inputs!D51,D18))),Inputs!D37)*10^9*Inputs!D54+D18*D11*1024^3 | E21: bytes
A22: t₁ = Th₁ / (N_model · BS₁) per-session | B22: Приводим aggregate-пропускную к per-session | C22: calc | D22: =IF(AND(Sizing!D12>0,D7>0),D8/(Sizing!D12*D7),0) | E22: tok/s/sess.
A23: t₂ = Th₂ / (N_model · BS₂) | C23: calc | D23: =IF(AND(Sizing!D12>0,D18>0),D19/(Sizing!D12*D18),0) | E23: tok/s/sess.
A24: O_fixed (выведено из 2 прогонов) | B24: O = (t₂·D₂ − t₁·D₁) / (1024³ · (t₁ − t₂)); в GiB. Если ≤ 0 → O_fixed = 0. | C24: calc | D24: =IF(ABS(D22-D23)>0.01,(D23*D21-D22*D20)/(1024^3*(D22-D23)),0) | E24: GiB
A25: η_core (выведено из 2 прогонов) | B25: η_core = t₁ × (D₁ + O×1024³) / (BW × 10⁹); при O_fixed=0 совпадает с η_mem одноточечной калибровки. | C25: calc | D25: =IF(AND(D22>0,Inputs!D28>0),D22*(D20+D24*1024^3)/(Inputs!D28*10^9),0) | E25: -
A26: Валидность 2-точечного фита | B26: Требования: |t₁−t₂|/max(t₁,t₂) ≥ 20%, O_fixed ≥ 0, η_core ∈ (0, 1). Иначе проверьте: GPU/модель/квант в Inputs совпадают с реальностью, BS разнесены (например, 1 vs 16). | C26: calc | D26: =IF(AND(D22>0,D23>0),IF(ABS(D22-D23)/MAX(D22,D23)<0.2,"⚠ t₁ и t₂ слишком близки (< 20%): возьмите более разные BS",IF(D24<0,"⚠ O_fixed < 0 — dense модель или шум: выставьте O_fixed = 0",IF(OR(D25<=0,D25>1),"⚠ η_core вне диапазона (0,1): проверьте Inputs (GPU, модель, квант)","✓ валидный фит: скопируйте O_fixed и η_core в Inputs"))),"(введите данные обоих прогонов)") | E26: status
A28: Prefill-heavy прогон (длинный prompt, короткий output)
A29: Th_pf^observed | B29: Total throughput − Output throughput | C29: INPUT | D29: 8000 | E29: tok/s
A30: SL_pf прогона (средний prompt) | B30: min-prompt-length ≈ 7000-9000 | C30: INPUT | D30: 8000 | E30: tokens
A31: η_pf (выведено из прогона) | B31: Е.3: η_pf = Th_pf^obs · (FPS + 4·L·d_attn^pf·SL_pf) / (F_count · N). Без делителя BS. | C31: calc | D31: =IF(AND(Sizing!D26>0,Sizing!D12>0),D29*(Sizing!D25+4*Inputs!D38*Inputs!D90*D30)/(Sizing!D26*Sizing!D12),0) | E31: -
A33: Самопроверка по закону Литтла (Приложение Е.4)
A34: λ: request throughput (из EvalScope) | B34: Запросов/с из прогона | C34: INPUT | D34: 10 | E34: req/s
A35: W: average latency (из EvalScope) | B35: Средняя задержка, сек | C35: INPUT | D35: 3 | E35: s
A36: N = λ · W (ожидаемая концентрация) | B36: Должна быть близка к BS | C36: calc | D36: =D34*D35 | E36: -
A37: Проверка: |N - BS| / BS ≤ 10% | B37: Если выходит — прогон недостоверен | C37: calc | D37: =IF(D7>0,IF(ABS(D36-D7)/D7<=0.1,"✓ OK","✗ FAIL: пересмотрите прогон"),"(нет BS)") | E37: status
A39: Рекомендации по применению
A40: Полученные η_mem, η_pf, η_dec скопируйте в соответствующие поля Inputs!D для данной пары (модель, GPU, движок). При смене модели, квантизации или версии инференс-движка повторите калибровку. η_dec валиден только для compute-bound decode — см. диагностику выше; для MoE-моделей decode обычно memory-bandwidth-bound, и η_dec слабо влияет на сайзинг (используйте типовые 0.02-0.05 из §Е.5).

Sheet Reference
A1: Каталог GPU (генерируется из каталога API: gpu_data.json + gpu_overrides.json)
A2: GPU | B2: Memory (GiB) | C2: FLOPS FP16 (TFLOPS) | D2: BW_GPU (GB/s) | E2: Memory type | F2: id
A3: AMD Instinct MI100 (Arcturus) | B3: 32 | C3: 184.6 | D3: 1228.8 | E3: HBM2 | F3: amd-amd-instinct-mi100-arcturus
A4: AMD Instinct MI210 (Aldebaran) | B4: 64 | C4: 181 | D4: 1638.4 | E4: HBM2E | F4: amd-amd-instinct-mi210-aldebaran
A5: AMD Instinct MI250 (Aldebaran) | B5: 64 | C5: 362.1 | D5: 1638.4 | E5: HBM2E | F5: amd-amd-instinct-mi250-aldebaran
A6: AMD Instinct MI250X (Aldebaran) | B6: 64 | C6: 383 | D6: 1638.4 | E6: HBM2E | F6: amd-amd-instinct-mi250x-aldebaran
A7: AMD Instinct MI300A (Antares) | B7: 128 | C7: 980.6 | D7: 5300 | E7: HBM3 | F7: amd-amd-instinct-mi300a-antares
A8: AMD Instinct MI300X (Aqua Vanjaram) | B8: 192 | C8: 1307.4 | D8: 5300 | E8: HBM3 | F8: amd-amd-instinct-mi300x-aqua-vanjaram
A9: AMD Instinct MI325X | B9: 256 | C9: 1307.4 | D9: 6000 | E9: HBM3E | F9: amd-instinct-mi325x
A10: AMD Instinct MI350X | B10: 288 | C10: 2300 | D10: 8000 | E10: HBM3E | F10: amd-amd-instinct-mi350x
A11: AMD Instinct MI355X | B11: 288 | C11: 2516.6 | D11: 8000 | E11: HBM3E | F11: amd-amd-instinct-mi355x
A12: NVIDIA A10 GPU accelerator (PCIe card) | B12: 24 | C12: 125 | D12: 600 | E12: GDDR6 | F12: nvidia-a10-gpu-accelerator-pcie-card
A13: NVIDIA A100 GPU accelerator (PCIe card) | B13: 80 | C13: 312 | D13: 1935 | E13: HBM2 | F13: nvidia-a100-gpu-accelerator-pcie-card
A14: NVIDIA A100 PCIe 40GB | B14: 40 | C14: 312 | D14: 1555 | E14: HBM2 | F14: nvidia-a100-pcie-40gb
... A35: NVIDIA V100S PCIe 32GB | B35: 32 | C35: 130 | D35: 1134 | E35: HBM2 | F35: nvidia-v100s-pcie-32gb
A64: Каталог LLM моделей (генерируется из llm_data.json)
A65: LLM | B65: P_total (B) | C65: P_active (B) | D65: L | E65: H | F65: N_attention | G65: N_kv | H65: head_dim | I65: Arch | J65: TS_max | K65: kv_lora_rank | L65: qk_rope_head_dim | M65: P_dense (B) | N65: P_moe (B) | O65: k_moe | P65: N_experts
A66: Qwen3-30B-A3B | B66: 30 | C66: 3 | D66: 48 | E66: 2048 | F66: 32 | G66: 4 | H66: 128 | I66: MoE/GQA | J66: 40960 | K66: 0 | L66: 0 | M66: 1.54 | N66: 28.99 | O66: 8 | P66: 128
A67: Qwen3-32B | B67: 32 | C67: 32 | D67: 64 | E67: 5120 | F67: 64 | G67: 8 | H67: 128 | I67: dense/GQA | J67: 40960 | K67: 0 | L67: 0 | M67: 0 | N67: 0 | O67: 0 | P67: 0
A68: Qwen3-235B-A22B | B68: 235 | C68: 22 | D68: 94 | E68: 4096 | F68: 64 | G68: 4 | H68: 128 | I68: MoE/GQA | J68: 40960 | K68: 0 | L68: 0 | M68: 8 | N68: 227.1 | O68: 8 | P68: 128
A69: Qwen3-30B-A3B-Instruct-2507 | B69: 30 | C69: 3 | D69: 48 | E69: 2048 | F69: 32 | G69: 4 | H69: 128 | I69: MoE/GQA | J69: 262144 | K69: 0 | L69: 0 | M69: 1.54 | N69: 28.99 | O69: 8 | P69: 128
A70: Qwen3-30B-A3B-Thinking-2507 | B70: 30 | C70: 3 | D70: 48 | E70: 2048 | F70: 32 | G70: 4 | H70: 128 | I70: MoE/GQA | J70: 262144 | K70: 0 | L70: 0 | M70: 1.54 | N70: 28.99 | O70: 8 | P70: 128
A71: Qwen3-235B-A22B-Instruct-2507 | B71: 235 | C71: 22 | D71: 94 | E71: 4096 | F71: 64 | G71: 4 | H71: 128 | I71: MoE/GQA | J71: 262144 | K71: 0 | L71: 0 | M71: 8 | N71: 227.1 | O71: 8 | P71: 128
A72: Qwen3-235B-A22B-Thinking-2507 | B72: 235 | C72: 22 | D72: 94 | E72: 4096 | F72: 64 | G72: 4 | H72: 128 | I72: MoE/GQA | J72: 262144 | K72: 0 | L72: 0 | M72: 8 | N72: 227.1 | O72: 8 | P72: 128
A73: Qwen3-Coder-30B-A3B-Instruct | B73: 30 | C73: 3 | D73: 48 | E73: 2048 | F73: 32 | G73: 4 | H73: 128 | I73: MoE/GQA | J73: 262144 | K73: 0 | L73: 0 | M73: 1.54 | N73: 28.99 | O73: 8 | P73: 128
A74: Qwen3-Coder-480B-A35B-Instruct | B74: 480 | C74: 35 | D74: 62 | E74: 6144 | F74: 96 | G74: 8 | H74: 128 | I74: MoE/GQA | J74: 262144 | K74: 0 | L74: 0 | M74: 12.07 | N74: 468.08 | O74: 8 | P74: 160
A75: Qwen3.5-27B | B75: 27 | C75: 27 | D75: 64 | E75: 5120 | F75: 24 | G75: 4 | H75: 256 | I75: dense/GQA | J75: 262144 | K75: 0 | L75: 0 | M75: 0 | N75: 0 | O75: 0 | P75: 0
A76: Qwen3.5-35B-A3B | B76: 35 | C76: 3 | D76: 40 | E76: 2048 | F76: 16 | G76: 2 | H76: 256 | I76: MoE/GQA | J76: 262144 | K76: 0 | L76: 0 | M76: 2.79 | N76: 32.21 | O76: 8 | P76: 256
A77: Qwen3.5-122B-A10B | B77: 122 | C77: 10 | D77: 48 | E77: 3072 | F77: 32 | G77: 2 | H77: 256 | I77: MoE/GQA | J77: 262144 | K77: 0 | L77: 0 | M77: 5.85 | N77: 116.15 | O77: 8 | P77: 256
... A126: GPT-OSS-120B | B126: 117 | C126: 5 | D126: 36 | E126: 2880 | F126: 64 | G126: 8 | H126: 64 | I126: MoE/GQA | J126: 131072 | K126: 0 | L126: 0 | M126: 2.13 | N126: 114.66 | O126: 4 | P126: 128
A267: Квантизация весов (методика §3.1, core/methodology_constants.py)
A268: Формат | B268: B_quant (байт) | C268: Описание
A269: FP32 | B269: 4 | C269: Полная точность — обучение и исследование
A270: FP16 | B270: 2 | C270: Стандарт для инференса с высокой точностью
A271: BF16 | B271: 2 | C271: Стандарт для Qwen/Llama/DeepSeek native weights
A272: FP8 | B272: 1 | C272: Baseline для современных инференс-движков
A273: INT8 | B273: 1 | C273: W8A8/W8A16 (SmoothQuant, LLM.int8)
A274: FP4 | B274: 0.5 | C274: NVFP4/MXFP4 на Blackwell (B200/GB200/B300)
A275: INT4 | B275: 0.5 | C275: GPTQ/AWQ — агрессивная квантизация
